Workbook

Sheet Sheet2
B3: Column Labels
B4: A1808 | D4: A1809 | F4: A1810 | H4: A1811 | J4: A1835 | L4: A1838 | N4: A1841 | P4: A1862 | R4: A1863 | T4: A1864 | V4: A1868 | X4: A1870 | Z4: A2027 | AB4: A2028 | AD4: A2037 | AF4: A2056 | AH4: A2064 | AJ4: A2075 | AL4: A2088 | AN4: A2269 | AP4: A2282 | AR4: A2406 | AT4: A2408 | AV4: A2409 | AX4: A2410 | AZ4: A2411 | BB4: A2412 | BD4: A2413 | BF4: A2414 | BH4: A2415 | BJ4: A2416 | BL4: A2417 | BN4: A2418 | BP4: A2419 | BR4: A2420 | BT4: A2549 | BV4: A2550 | BX4: A2552 | BZ4: A2554 | CB4: A2560 | CD4: A2561 | CF4: A2563 | CH4: A2564 | CJ4: A2565 | CL4: A2567 | CN4: A2568 | CP4: A2569 | CR4: A2570 | CT4: A2571 | CV4: A2572 | CX4: (blank)
A5: Row Labels | B5: Sum of Stocking b4 thin | C5: Sum of Stocking b4 thin2 | D5: Sum of Stocking b4 thin | E5: Sum of Stocking b4 thin2 | F5: Sum of Stocking b4 thin | G5: Sum of Stocking b4 thin2 | H5: Sum of Stocking b4 thin | I5: Sum of Stocking b4 thin2 | J5: Sum of Stocking b4 thin | K5: Sum of Stocking b4 thin2 | L5: Sum of Stocking b4 thin | M5: Sum of Stocking b4 thin2 | N5: Sum of Stocking b4 thin | O5: Sum of Stocking b4 thin2 | P5: Sum of Stocking b4 thin | Q5: Sum of Stocking b4 thin2 | R5: Sum of Stocking b4 thin | S5: Sum of Stocking b4 thin2 | T5: Sum of Stocking b4 thin | U5: Sum of Stocking b4 thin2 | V5: Sum of Stocking b4 thin | W5: Sum of Stocking b4 thin2 | X5: Sum of Stocking b4 thin | Y5: Sum of Stocking b4 thin2 | Z5: Sum of Stocking b4 thin | AA5: Sum of Stocking b4 thin2 | AB5: Sum of Stocking b4 thin | AC5: Sum of Stocking b4 thin2 | AD5: Sum of Stocking b4 thin | AE5: Sum of Stocking b4 thin2 | AF5: Sum of Stocking b4 thin | AG5: Sum of Stocking b4 thin2 | AH5: Sum of Stocking b4 thin | AI5: Sum of Stocking b4 thin2 | AJ5: Sum of Stocking b4 thin | AK5: Sum of Stocking b4 thin2 | AL5: Sum of Stocking b4 thin | AM5: Sum of Stocking b4 thin2 | AN5: Sum of Stocking b4 thin | AO5: Sum of Stocking b4 thin2 | AP5: Sum of Stocking b4 thin | AQ5: Sum of Stocking b4 thin2 | AR5: Sum of Stocking b4 thin | AS5: Sum of Stocking b4 thin2 | AT5: Sum of Stocking b4 thin | AU5: Sum of Stocking b4 thin2 | AV5: Sum of Stocking b4 thin | AW5: Sum of Stocking b4 thin2 | AX5: Sum of Stocking b4 thin | AY5: Sum of Stocking b4 thin2 | AZ5: Sum of Stocking b4 thin | BA5: Sum of Stocking b4 thin2 | BB5: Sum of Stocking b4 thin | BC5: Sum of Stocking b4 thin2 | BD5: Sum of Stocking b4 thin | BE5: Sum of Stocking b4 thin2 | BF5: Sum of Stocking b4 thin | BG5: Sum of Stocking b4 thin2 | BH5: Sum of Stocking b4 thin | BI5: Sum of Stocking b4 thin2 | BJ5: Sum of Stocking b4 thin | BK5: Sum of Stocking b4 thin2 | BL5: Sum of Stocking b4 thin | BM5: Sum of Stocking b4 thin2 | BN5: Sum of Stocking b4 thin | BO5: Sum of Stocking b4 thin2 | BP5: Sum of Stocking b4 thin | BQ5: Sum of Stocking b4 thin2 | BR5: Sum of Stocking b4 thin | BS5: Sum of Stocking b4 thin2 | BT5: Sum of Stocking b4 thin | BU5: Sum of Stocking b4 thin2 | BV5: Sum of Stocking b4 thin | BW5: Sum of Stocking b4 thin2 | BX5: Sum of Stocking b4 thin | BY5: Sum of Stocking b4 thin2 | BZ5: Sum of Stocking b4 thin | CA5: Sum of Stocking b4 thin2 | CB5: Sum of Stocking b4 thin | CC5: Sum of Stocking b4 thin2 | CD5: Sum of Stocking b4 thin | CE5: Sum of Stocking b4 thin2 | CF5: Sum of Stocking b4 thin | CG5: Sum of Stocking b4 thin2 | CH5: Sum of Stocking b4 thin | CI5: Sum of Stocking b4 thin2 | CJ5: Sum of Stocking b4 thin | CK5: Sum of Stocking b4 thin2 | CL5: Sum of Stocking b4 thin | CM5: Sum of Stocking b4 thin2 | CN5: Sum of Stocking b4 thin | CO5: Sum of Stocking b4 thin2 | CP5: Sum of Stocking b4 thin | CQ5: Sum of Stocking b4 thin2 | CR5: Sum of Stocking b4 thin | CS5: Sum of Stocking b4 thin2 | CT5: Sum of Stocking b4 thin | CU5: Sum of Stocking b4 thin2 | CV5: Sum of Stocking b4 thin | CW5: Sum of Stocking b4 thin2 | CX5: Sum of Stocking b4 thin | CY5: Sum of Stocking b4 thin2
A6: 0 | B6: 310 | C6: 310 | D6: 925 | E6: 925 | F6: 1400 | G6: 1400 | H6: 1050 | I6: 1050 | J6: 675 | K6: 675 | L6: 925 | M6: 925 | N6: 650 | O6: 650 | P6: 240 | Q6: 240 | R6: 600 | S6: 600 | T6: 250 | U6: 250 | V6: 260 | W6: 260 | X6: 230 | Y6: 230 | Z6: 873 | AA6: 873 | AB6: 541 | AC6: 541 | AD6: 835 | AE6: 835 | AF6: 469 | AG6: 469 | AH6: 340 | AI6: 340 | AJ6: 320 | AK6: 320 | AL6: 330 | AM6: 330 | AN6: 583 | AO6: 583 | AP6: 600 | AQ6: 600 | AR6: 222 | AS6: 222 | AT6: 211 | AU6: 211 | AV6: 233 | AW6: 233 | AX6: 233 | AY6: 233 | AZ6: 211 | BA6: 211 | BB6: 222 | BC6: 222 | BD6: 233 | BE6: 233 | BF6: 233 | BG6: 233 | BH6: 233 | BI6: 233 | BJ6: 233 | BK6: 233 | BL6: 233 | BM6: 233 | BN6: 222 | BO6: 222 | BP6: 233 | BQ6: 233 | BR6: 233 | BS6: 233 | BT6: 340 | BU6: 340 | BV6: 250 | BW6: 250 | BX6: 200 | BY6: 200 | BZ6: 310 | CA6: 310 | CB6: 270 | CC6: 270 | CD6: 240 | CE6: 240 | CF6: 280 | CG6: 280 | CH6: 340 | CI6: 340 | CJ6: 250 | CK6: 250 | CL6: 220 | CM6: 220 | CN6: 220 | CO6: 220 | CP6: 270 | CQ6: 270 | CR6: 270 | CS6: 270 | CT6: 270 | CU6: 270 | CV6: 260 | CW6: 260
A7: 1 | B7: 310 | C7: 310 | D7: 925 | E7: 925 | F7: 1400 | G7: 1400 | H7: 1050 | I7: 1050 | J7: 675 | K7: 675 | L7: 925 | M7: 925 | N7: 650 | O7: 650 | P7: 240 | Q7: 240 | R7: 600 | S7: 600 | T7: 250 | U7: 250 | V7: 260 | W7: 260 | X7: 230 | Y7: 230 | Z7: 873 | AA7: 873 | AB7: 541 | AC7: 541 | AD7: 835 | AE7: 835 | AF7: 465.8 | AG7: 469 | AH7: 340 | AI7: 340 | AJ7: 319.4 | AK7: 320 | AL7: 330 | AM7: 330 | AN7: 583 | AO7: 583 | AP7: 600 | AQ7: 600 | AR7: 222 | AS7: 222 | AT7: 211 | AU7: 211 | AV7: 233 | AW7: 233 | AX7: 233 | AY7: 233 | AZ7: 211 | BA7: 211 | BB7: 222 | BC7: 222 | BD7: 233 | BE7: 233 | BF7: 233 | BG7: 233 | BH7: 233 | BI7: 233 | BJ7: 233 | BK7: 233 | BL7: 233 | BM7: 233 | BN7: 222 | BO7: 222 | BP7: 233 | BQ7: 233 | BR7: 233 | BS7: 233 | BT7: 339.5 | BU7: 340 | BV7: 249.5 | BW7: 250 | BX7: 200 | BY7: 200 | BZ7: 310 | CA7: 310 | CB7: 269.4 | CC7: 270 | CD7: 240 | CE7: 240 | CF7: 280 | CG7: 280 | CH7: 339.6 | CI7: 340 | CJ7: 250 | CK7: 250 | CL7: 219.6 | CM7: 220 | CN7: 220 | CO7: 220 | CP7: 270 | CQ7: 270 | CR7: 268.6 | CS7: 270 | CT7: 270 | CU7: 270 | CV7: 259.6 | CW7: 260
A8: 2 | B8: 310 | C8: 310 | D8: 925 | E8: 925 | F8: 1400 | G8: 1400 | H8: 1050 | I8: 1050 | J8: 674.9 | K8: 675 | L8: 924.9 | M8: 925 | N8: 649.9 | O8: 650 | P8: 240 | Q8: 240 | R8: 600 | S8: 600 | T8: 250 | U8: 250 | V8: 260 | W8: 260 | X8: 230 | Y8: 230 | Z8: 873 | AA8: 873 | AB8: 540.9 | AC8: 541 | AD8: 834.8 | AE8: 835 | AF8: 462.6 | AG8: 469 | AH8: 340 | AI8: 340 | AJ8: 318.8 | AK8: 320 | AL8: 330 | AM8: 330 | AN8: 583 | AO8: 583 | AP8: 599.9 | AQ8: 600 | AR8: 222 | AS8: 222 | AT8: 211 | AU8: 211 | AV8: 233 | AW8: 233 | AX8: 233 | AY8: 233 | AZ8: 211 | BA8: 211 | BB8: 222 | BC8: 222 | BD8: 233 | BE8: 233 | BF8: 233 | BG8: 233 | BH8: 233 | BI8: 233 | BJ8: 233 | BK8: 233 | BL8: 233 | BM8: 233 | BN8: 222 | BO8: 222 | BP8: 233 | BQ8: 233 | BR8: 233 | BS8: 233 | BT8: 339.1 | BU8: 340 | BV8: 249 | BW8: 250 | BX8: 200 | BY8: 200 | BZ8: 310 | CA8: 310 | CB8: 268.9 | CC8: 270 | CD8: 240 | CE8: 240 | CF8: 280 | CG8: 280 | CH8: 339.2 | CI8: 340 | CJ8: 250 | CK8: 250 | CL8: 219.2 | CM8: 220 | CN8: 220 | CO8: 220 | CP8: 270 | CQ8: 270 | CR8: 267.3 | CS8: 270 | CT8: 270 | CU8: 270 | CV8: 259.2 | CW8: 260
A9: 3 | B9: 310 | C9: 310 | D9: 924.8 | E9: 925 | F9: 1399.6 | G9: 1400 | H9: 1049.5 | I9: 1049.5 | J9: 674.6 | K9: 674.7 | L9: 924.4 | M9: 924.6 | N9: 649.6 | O9: 649.7 | P9: 240 | Q9: 239.9 | R9: 600 | S9: 599.7 | T9: 250 | U9: 249.9 | V9: 260 | W9: 259.9 | X9: 230 | Y9: 229.9 | Z9: 872.6 | AA9: 873 | AB9: 540.7 | AC9: 540.8 | AD9: 834.4 | AE9: 834.6 | AF9: 459.5 | AG9: 468.8 | AH9: 340 | AI9: 339.8 | AJ9: 318.2 | AK9: 319.9 | AL9: 330 | AM9: 329.8 | AN9: 582.7 | AO9: 582.7 | AP9: 599.6 | AQ9: 599.7 | AR9: 222 | AS9: 221.9 | AT9: 211 | AU9: 210.9 | AV9: 233 | AW9: 232.9 | AX9: 233 | AY9: 232.9 | AZ9: 211 | BA9: 210.9 | BB9: 222 | BC9: 221.9 | BD9: 233 | BE9: 232.9 | BF9: 233 | BG9: 232.9 | BH9: 233 | BI9: 232.9 | BJ9: 233 | BK9: 232.9 | BL9: 233 | BM9: 232.9 | BN9: 222 | BO9: 221.9 | BP9: 233 | BQ9: 232.9 | BR9: 233 | BS9: 232.9 | BT9: 338.6 | BU9: 339.8 | BV9: 248.6 | BW9: 249.9 | BX9: 200 | BY9: 199.9 | BZ9: 310 | CA9: 309.9 | CB9: 268.4 | CC9: 269.9 | CD9: 240 | CE9: 239.9 | CF9: 280 | CG9: 279.9 | CH9: 338.8 | CI9: 339.8 | CJ9: 250 | CK9: 249.9 | CL9: 218.8 | CM9: 219.9 | CN9: 220 | CO9: 219.9 | CP9: 270 | CQ9: 269.9 | CR9: 265.9 | CS9: 269.9 | CT9: 270 | CU9: 269.9 | CV9: 258.7 | CW9: 259.9
A10: 4 | B10: 310 | C10: 309.9 | D10: 924.4 | E10: 924.6 | F10: 1399 | G10: 1399.4 | H10: 1049 | I10: 1049 | J10: 674.3 | K10: 674.4 | L10: 924 | M10: 924.2 | N10: 649.3 | O10: 649.4 | P10: 240 | Q10: 239.8 | R10: 600 | S10: 599.4 | T10: 250 | U10: 249.8 | V10: 260 | W10: 259.8 | X10: 230 | Y10: 229.8 | Z10: 872.2 | AA10: 872.6 | AB10: 540.4 | AC10: 540.5 | AD10: 834 | AE10: 834.2 | AF10: 456.3 | AG10: 468.6 | AH10: 340 | AI10: 339.7 | AJ10: 317.6 | AK10: 319.7 | AL10: 330 | AM10: 329.7 | AN10: 582.5 | AO10: 582.5 | AP10: 599.4 | AQ10: 599.4 | AR10: 222 | AS10: 221.8 | AT10: 211 | AU10: 210.8 | AV10: 233 | AW10: 232.8 | AX10: 233 | AY10: 232.8 | AZ10: 211 | BA10: 210.8 | BB10: 222 | BC10: 221.8 | BD10: 233 | BE10: 232.8 | BF10: 233 | BG10: 232.8 | BH10: 233 | BI10: 232.8 | BJ10: 233 | BK10: 232.8 | BL10: 233 | BM10: 232.8 | BN10: 222 | BO10: 221.8 | BP10: 233 | BQ10: 232.8 | BR10: 233 | BS10: 232.8 | BT10: 338.1 | BU10: 339.7 | BV10: 248.1 | BW10: 249.8 | BX10: 200 | BY10: 199.8 | BZ10: 310 | CA10: 309.7 | CB10: 267.8 | CC10: 269.8 | CD10: 240 | CE10: 239.8 | CF10: 280 | CG10: 279.7 | CH10: 338.5 | CI10: 339.7 | CJ10: 250 | CK10: 249.8 | CL10: 218.4 | CM10: 219.8 | CN10: 220 | CO10: 219.8 | CP10: 270 | CQ10: 269.8 | CR10: 264.6 | CS10: 269.8 | CT10: 270 | CU10: 269.8 | CV10: 258.3 | CW10: 259.8
A11: 5 | B11: 310 | C11: 309.7 | D11: 924 | E11: 924.2 | F11: 1398.3 | G11: 1398.7 | H11: 1048.5 | I11: 1048.6 | J11: 674 | K11: 674.1 | L11: 923.6 | M11: 923.7 | N11: 649 | O11: 649.1 | P11: 240 | Q11: 239.7 | R11: 600 | S11: 599.2 | T11: 250 | U11: 249.7 | V11: 260 | W11: 259.6 | X11: 230 | Y11: 229.7 | Z11: 871.8 | AA11: 872.2 | AB11: 540.2 | AC11: 540.3 | AD11: 833.6 | AE11: 833.8 | AF11: 453.2 | AG11: 468.4 | AH11: 340 | AI11: 339.5 | AJ11: 317 | AK11: 319.6 | AL11: 330 | AM11: 329.5 | AN11: 582.2 | AO11: 582.2 | AP11: 599.1 | AQ11: 599.2 | AR11: 222 | AS11: 221.7 | AT11: 211 | AU11: 210.7 | AV11: 233 | AW11: 232.7 | AX11: 233 | AY11: 232.7 | AZ11: 211 | BA11: 210.7 | BB11: 222 | BC11: 221.7 | BD11: 233 | BE11: 232.7 | BF11: 233 | BG11: 232.7 | BH11: 233 | BI11: 232.7 | BJ11: 233 | BK11: 232.7 | BL11: 233 | BM11: 232.7 | BN11: 222 | BO11: 221.7 | BP11: 233 | BQ11: 232.7 | BR11: 233 | BS11: 232.7 | BT11: 337.6 | BU11: 339.5 | BV11: 247.6 | BW11: 249.7 | BX11: 200 | BY11: 199.7 | BZ11: 310 | CA11: 309.6 | CB11: 267.3 | CC11: 269.6 | CD11: 240 | CE11: 239.7 | CF11: 280 | CG11: 279.6 | CH11: 338.1 | CI11: 339.5 | CJ11: 250 | CK11: 249.7 | CL11: 218 | CM11: 219.7 | CN11: 220 | CO11: 219.7 | CP11: 270 | CQ11: 269.6 | CR11: 263.2 | CS11: 269.6 | CT11: 270 | CU11: 269.6 | CV11: 257.9 | CW11: 259.6
A12: 6 | B12: 310 | C12: 309.6 | D12: 923.5 | E12: 923.7 | F12: 1397.7 | G12: 1398.1 | H12: 1048 | I12: 1048.1 | J12: 673.7 | K12: 673.8 | L12: 923.1 | M12: 923.3 | N12: 648.7 | O12: 648.8 | P12: 240 | Q12: 239.6 | R12: 600 | S12: 598.9 | T12: 250 | U12: 249.5 | V12: 260 | W12: 259.5 | X12: 230 | Y12: 229.6 | Z12: 871.4 | AA12: 871.8 | AB12: 539.9 | AC12: 540 | AD12: 833.1 | AE12: 833.4 | AF12: 450.1 | AG12: 468.1 | AH12: 340 | AI12: 339.4 | AJ12: 316.5 | AK12: 319.4 | AL12: 330 | AM12: 329.4 | AN12: 581.9 | AO12: 581.9 | AP12: 598.8 | AQ12: 598.9 | AR12: 222 | AS12: 221.6 | AT12: 211 | AU12: 210.6 | AV12: 233 | AW12: 232.6 | AX12: 233 | AY12: 232.6 | AZ12: 211 | BA12: 210.6 | BB12: 222 | BC12: 221.6 | BD12: 233 | BE12: 232.6 | BF12: 233 | BG12: 232.6 | BH12: 233 | BI12: 232.6 | BJ12: 233 | BK12: 232.6 | BL12: 233 | BM12: 232.6 | BN12: 222 | BO12: 221.6 | BP12: 233 | BQ12: 232.6 | BR12: 233 | BS12: 232.6 | BT12: 337.2 | BU12: 339.4 | BV12: 247.2 | BW12: 249.5 | BX12: 200 | BY12: 199.6 | BZ12: 310 | CA12: 309.4 | CB12: 266.7 | CC12: 269.5 | CD12: 240 | CE12: 239.6 | CF12: 280 | CG12: 279.5 | CH12: 337.7 | CI12: 339.4 | CJ12: 250 | CK12: 249.5 | CL12: 217.6 | CM12: 219.6 | CN12: 220 | CO12: 219.6 | CP12: 270 | CQ12: 269.5 | CR12: 261.9 | CS12: 269.5 | CT12: 270 | CU12: 269.5 | CV12: 257.5 | CW12: 259.5
A13: 7 | B13: 310 | C13: 309.4 | D13: 549.7 | E13: 550 | F13: 824.6 | G13: 825 | H13: 675 | I13: 675 | J13: 673.4 | K13: 673.4 | L13: 922.6 | M13: 922.8 | N13: 648.4 | O13: 648.5 | P13: 240 | Q13: 239.4 | R13: 600 | S13: 598.6 | T13: 250 | U13: 249.4 | V13: 260 | W13: 259.4 | X13: 230 | Y13: 229.5 | Z13: 871 | AA13: 871.4 | AB13: 539.7 | AC13: 539.8 | AD13: 832.3 | AE13: 832.9 | AF13: 447.1 | AG13: 467.9 | AH13: 340 | AI13: 339.2 | AJ13: 315.9 | AK13: 319.3 | AL13: 330 | AM13: 329.2 | AN13: 581.6 | AO13: 581.7 | AP13: 598.5 | AQ13: 598.6 | AR13: 222 | AS13: 221.5 | AT13: 211 | AU13: 210.5 | AV13: 233 | AW13: 232.5 | AX13: 233 | AY13: 232.5 | AZ13: 211 | BA13: 210.5 | BB13: 222 | BC13: 221.5 | BD13: 233 | BE13: 232.5 | BF13: 233 | BG13: 232.5 | BH13: 233 | BI13: 232.5 | BJ13: 233 | BK13: 232.5 | BL13: 233 | BM13: 232.5 | BN13: 222 | BO13: 221.5 | BP13: 233 | BQ13: 232.5 | BR13: 233 | BS13: 232.5 | BT13: 336.7 | BU13: 339.2 | BV13: 246.7 | BW13: 249.4 | BX13: 200 | BY13: 199.5 | BZ13: 310 | CA13: 309.3 | CB13: 266.2 | CC13: 269.4 | CD13: 240 | CE13: 239.4 | CF13: 280 | CG13: 279.4 | CH13: 337.3 | CI13: 339.2 | CJ13: 250 | CK13: 249.4 | CL13: 217.2 | CM13: 219.5 | CN13: 220 | CO13: 219.5 | CP13: 270 | CQ13: 269.4 | CR13: 260.6 | CS13: 269.4 | CT13: 270 | CU13: 269.4 | CV13: 257.1 | CW13: 259.4
A14: 8 | B14: 310 | C14: 309.3 | D14: 549.5 | E14: 549.7 | F14: 824.2 | G14: 824.6 | H14: 675 | I14: 674.7 | J14: 673 | K14: 673.1 | L14: 921.9 | M14: 922.2 | N14: 648 | O14: 648.2 | P14: 240 | Q14: 239.3 | R14: 600 | S14: 598.3 | T14: 250 | U14: 249.3 | V14: 260 | W14: 259.3 | X14: 230 | Y14: 229.4 | Z14: 870.6 | AA14: 871 | AB14: 539.4 | AC14: 539.5 | AD14: 830.9 | AE14: 831.9 | AF14: 444 | AG14: 467.7 | AH14: 340 | AI14: 339 | AJ14: 315.3 | AK14: 319.1 | AL14: 330 | AM14: 329.1 | AN14: 366.8 | AO14: 581.4 | AP14: 383 | AQ14: 598.3 | AR14: 222 | AS14: 221.4 | AT14: 211 | AU14: 210.4 | AV14: 233 | AW14: 232.4 | AX14: 233 | AY14: 232.4 | AZ14: 211 | BA14: 210.4 | BB14: 222 | BC14: 221.4 | BD14: 233 | BE14: 232.4 | BF14: 233 | BG14: 232.4 | BH14: 233 | BI14: 232.4 | BJ14: 233 | BK14: 232.4 | BL14: 233 | BM14: 232.4 | BN14: 222 | BO14: 221.4 | BP14: 233 | BQ14: 232.4 | BR14: 233 | BS14: 232.4 | BT14: 336.2 | BU14: 339.1 | BV14: 246.2 | BW14: 249.3 | BX14: 200 | BY14: 199.4 | BZ14: 310 | CA14: 309.1 | CB14: 265.6 | CC14: 269.2 | CD14: 240 | CE14: 239.3 | CF14: 280 | CG14: 279.2 | CH14: 336.9 | CI14: 339 | CJ14: 250 | CK14: 249.3 | CL14: 216.8 | CM14: 219.4 | CN14: 220 | CO14: 219.4 | CP14: 270 | CQ14: 269.2 | CR14: 259.3 | CS14: 269.2 | CT14: 270 | CU14: 269.3 | CV14: 256.7 | CW14: 259.3
A15: 9 | B15: 310 | C15: 309.1 | D15: 549.2 | E15: 549.5 | F15: 823.8 | G15: 824.2 | H15: 675 | I15: 674.3 | J15: 672.5 | K15: 672.7 | L15: 920.7 | M15: 921.3 | N15: 647.6 | O15: 647.8 | P15: 240 | Q15: 239.2 | R15: 600 | S15: 598 | T15: 250 | U15: 249.2 | V15: 260 | W15: 259.2 | X15: 230 | Y15: 229.3 | Z15: 870.1 | AA15: 870.5 | AB15: 539.1 | AC15: 539.2 | AD15: 828.4 | AE15: 830.2 | AF15: 441 | AG15: 467.4 | AH15: 340 | AI15: 338.8 | AJ15: 314.7 | AK15: 318.9 | AL15: 330 | AM15: 328.9 | AN15: 366.7 | AO15: 367 | AP15: 383 | AQ15: 383 | AR15: 222 | AS15: 221.3 | AT15: 211 | AU15: 210.3 | AV15: 233 | AW15: 232.3 | AX15: 233 | AY15: 232.2 | AZ15: 211 | BA15: 210.3 | BB15: 222 | BC15: 221.3 | BD15: 233 | BE15: 232.2 | BF15: 233 | BG15: 232.2 | BH15: 233 | BI15: 232.3 | BJ15: 233 | BK15: 232.3 | BL15: 233 | BM15: 232.3 | BN15: 222 | BO15: 221.3 | BP15: 233 | BQ15: 232.3 | BR15: 233 | BS15: 232.2 | BT15: 335.8 | BU15: 338.9 | BV15: 245.7 | BW15: 249.2 | BX15: 200 | BY15: 199.4 | BZ15: 310 | CA15: 309 | CB15: 265.1 | CC15: 269.1 | CD15: 240 | CE15: 239.2 | CF15: 280 | CG15: 279.1 | CH15: 336.5 | CI15: 338.9 | CJ15: 250 | CK15: 249.2 | CL15: 216.4 | CM15: 219.3 | CN15: 220 | CO15: 219.3 | CP15: 270 | CQ15: 269.1 | CR15: 257.9 | CS15: 269.1 | CT15: 270 | CU15: 269.1 | CV15: 256.2 | CW15: 259.2
A16: 10 | B16: 310 | C16: 309 | D16: 250 | E16: 549.2 | F16: 823.4 | G16: 823.8 | H16: 674.7 | I16: 673.9 | J16: 293.9 | K16: 300 | L16: 918.7 | M16: 919.6 | N16: 646.9 | O16: 647.2 | P16: 240 | Q16: 239.1 | R16: 600 | S16: 597.7 | T16: 250 | U16: 249.1 | V16: 260 | W16: 259 | X16: 230 | Y16: 229.2 | Z16: 869.4 | AA16: 870 | AB16: 538.8 | AC16: 538.9 | AD16: 824.9 | AE16: 827.5 | AF16: 438 | AG16: 467.1 | AH16: 340 | AI16: 338.6 | AJ16: 314.1 | AK16: 318.8 | AL16: 330 | AM16: 328.8 | AN16: 366.5 | AO16: 366.8 | AP16: 383 | AQ16: 382.8 | AR16: 222 | AS16: 221.2 | AT16: 211 | AU16: 210.2 | AV16: 233 | AW16: 232.1 | AX16: 233 | AY16: 232.1 | AZ16: 211 | BA16: 210.2 | BB16: 222 | BC16: 221.2 | BD16: 233 | BE16: 232.1 | BF16: 233 | BG16: 232.1 | BH16: 233 | BI16: 232.1 | BJ16: 233 | BK16: 232.1 | BL16: 233 | BM16: 232.1 | BN16: 222 | BO16: 221.2 | BP16: 233 | BQ16: 232.1 | BR16: 233 | BS16: 232.1 | BT16: 335.3 | BU16: 338.7 | BV16: 245.3 | BW16: 249.1 | BX16: 200 | BY16: 199.3 | BZ16: 310 | CA16: 308.8 | CB16: 264.5 | CC16: 268.9 | CD16: 240 | CE16: 239.1 | CF16: 280 | CG16: 278.9 | CH16: 336.1 | CI16: 338.6 | CJ16: 250 | CK16: 249 | CL16: 216 | CM16: 219.2 | CN16: 220 | CO16: 219.2 | CP16: 270 | CQ16: 268.9 | CR16: 256.6 | CS16: 268.9 | CT16: 270 | CU16: 269 | CV16: 255.8 | CW16: 259
A17: 11 | B17: 310 | C17: 308.9 | D17: 250 | E17: 250 | F17: 822.9 | G17: 823.4 | H17: 673.8 | I17: 673.2 | J17: 287.9 | K17: 299.8 | L17: 270 | M17: 916.9 | N17: 645.9 | O17: 646.3 | P17: 240 | Q17: 239 | R17: 600 | S17: 597.2 | T17: 250 | U17: 249 | V17: 260 | W17: 258.9 | X17: 230 | Y17: 229 | Z17: 868.4 | AA17: 869.3 | AB17: 538.3 | AC17: 538.6 | AD17: 820.1 | AE17: 823.4 | AF17: 435 | AG17: 466.7 | AH17: 340 | AI17: 338.3 | AJ17: 313.5 | AK17: 318.5 | AL17: 330 | AM17: 328.6 | AN17: 200 | AO17: 200 | AP17: 382.7 | AQ17: 382.5 | AR17: 222 | AS17: 221.1 | AT17: 211 | AU17: 210.1 | AV17: 233 | AW17: 232 | AX17: 233 | AY17: 232 | AZ17: 211 | BA17: 210.1 | BB17: 222 | BC17: 221.1 | BD17: 233 | BE17: 232 | BF17: 233 | BG17: 232 | BH17: 233 | BI17: 232 | BJ17: 233 | BK17: 232 | BL17: 233 | BM17: 232 | BN17: 222 | BO17: 221.1 | BP17: 233 | BQ17: 232 | BR17: 233 | BS17: 232 | BT17: 334.8 | BU17: 338.5 | BV17: 244.8 | BW17: 248.9 | BX17: 200 | BY17: 199.2 | BZ17: 310 | CA17: 308.6 | CB17: 264 | CC17: 268.7 | CD17: 240 | CE17: 238.9 | CF17: 280 | CG17: 278.7 | CH17: 335.8 | CI17: 338.3 | CJ17: 250 | CK17: 248.9 | CL17: 215.6 | CM17: 219 | CN17: 220 | CO17: 219 | CP17: 270 | CQ17: 268.6 | CR17: 255.3 | CS17: 268.7 | CT17: 270 | CU17: 268.8 | CV17: 255.4 | CW17: 258.9
... A34: 28 | B34: 308 | C34: 302.7 | D34: 247.2 | E34: 245.8 | F34: 337.3 | G34: 332.5 | H34: 568.8 | I34: 575.2 | J34: 226.4 | K34: 224.2 | L34: 268.2 | M34: 260.1 | N34: 248.5 | O34: 242.6 | P34: 236.8 | Q34: 232.4 | R34: 567.1 | S34: 527.7 | T34: 247.6 | U34: 243 | V34: 257.1 | W34: 251.6 | X34: 227.9 | Y34: 223.8 | Z34: 298.9 | AA34: 291.1 | AB34: 298.3 | AC34: 296.1 | AD34: 224.7 | AE34: 219.2 | AF34: 383.9 | AG34: 395.8 | AH34: 321.7 | AI34: 314.6 | AJ34: 297.5 | AK34: 302.9 | AL34: 315.7 | AM34: 313.7 | AN34: 200 | AO34: 196.6 | AP34: 356.7 | AQ34: 357.5 | AR34: 217.2 | AS34: 215.7 | AT34: 206.7 | AU34: 205.3 | AV34: 227.5 | AW34: 225.9 | AX34: 227.7 | AY34: 226.1 | AZ34: 206.9 | BA34: 205.5 | BB34: 217.6 | BC34: 216.2 | BD34: 227.1 | BE34: 225.3 | BF34: 227.6 | BG34: 226 | BH34: 227.9 | BI34: 226.4 | BJ34: 227.9 | BK34: 226.4 | BL34: 227.5 | BM34: 226 | BN34: 217.2 | BO34: 215.5 | BP34: 227.6 | BQ34: 226 | BR34: 227.7 | BS34: 226.1 | BT34: 320.3 | BU34: 322.5 | BV34: 235.8 | BW34: 233.3 | BX34: 198.2 | BY34: 194.5 | BZ34: 306.9 | CA34: 293.7 | CB34: 253.1 | CC34: 258.7 | CD34: 236.4 | CE34: 231.7 | CF34: 277.3 | CG34: 268.7 | CH34: 326.7 | CI34: 319.7 | CJ34: 245.1 | CK34: 241.6 | CL34: 208.7 | CM34: 205.8 | CN34: 216.8 | CO34: 212 | CP34: 264.4 | CQ34: 255.5 | CR34: 236 | CS34: 231.3 | CT34: 264.8 | CU34: 258.2 | CV34: 247.3 | CW34: 251.9
A35: (blank)

Sheet yield_tables_VBA
A1: Plot | B1: Index age | C1: Age | D1: Stocking b4 thin | E1: Stocking aft thin | F1: MTH | G1: Crown Lth | H1: Volume b4 thin | I1: Volume aft thin | J1: BA b4 thin | K1: BA aft thin | L1: DBH b4 thin | M1: DBH aft thin | N1: Mean Height | O1: Stocking aft thin | P1: MTH | Q1: Crown Lth | R1: Volume b4 thin | S1: Volume aft thin | T1: BA b4 thin | U1: BA aft thin | V1: DBH b4 thin | W1: DBH aft thin | X1: Mean Height | Y1: Event
A2: LowUC | B2: 25.4 | C2: 0 | D2: 310 | F2: 0.25 | H2: 0.001984 | J2: 0 | L2: 0 | N2: 0.24007082 | P2: 0.3 | Q2: 0 | R2: 0 | T2: 0 | V2: 0 | X2: 0.2
C3: 1 | D3: 310 | F3: 0.57418873 | H3: 0.007952462 | J3: 0 | L3: 0 | N3: 0.55138383 | P3: 0.6 | Q3: 0 | R3: 0 | T3: 0 | V3: 0 | X3: 0.6
C4: 2 | D4: 310 | F4: 1.2320062 | H4: 0.040767177 | J4: 0 | L4: 0 | N4: 1.183075 | P4: 1.2 | Q4: 0 | R4: 0 | T4: 0 | V4: 0 | X4: 1.2
C5: 3 | D5: 310 | F5: 2.0837734 | H5: 0.11788569 | J5: 0.011703426 | L5: 0.69324997 | N5: 2.0010128 | P5: 2.1 | Q5: 0 | R5: 0 | T5: 0.01 | V5: 0.5 | X5: 2
C6: 4 | D6: 310 | F6: 3.0602596 | H6: 0.25399783 | J6: 0.098818719 | L6: 2.0144336 | N6: 2.9387161 | P6: 3.1 | Q6: 0 | R6: 0.2 | T6: 0.07 | V6: 1.6 | X6: 3
C7: 5 | D7: 310 | F7: 4.1159482 | H7: 0.7175278 | J7: 0.28470976 | L7: 3.4192789 | N7: 3.9524762 | P7: 4.1 | Q7: 0 | R7: 0.6 | T7: 0.23 | V7: 3.1 | X7: 4
C8: 6 | D8: 310 | F8: 5.2184243 | H8: 1.5751608 | J8: 0.58516501 | L8: 4.9019912 | N8: 5.0111655 | P8: 5.2 | Q8: 0 | R8: 1.4 | T8: 0.53 | V8: 4.6 | X8: 5
C9: 7 | D9: 310 | F9: 6.343767 | H9: 3.0952376 | J9: 1.0508319 | L9: 6.5690108 | N9: 6.0918133 | P9: 6.4 | Q9: 0 | R9: 2.8 | T9: 0.97 | V9: 6.3 | X9: 6.1
C10: 8 | D10: 310 | F10: 7.4740265 | H10: 5.482142 | J10: 1.6940025 | L10: 8.3404672 | N10: 7.1771826 | P10: 7.5 | Q10: 0 | R10: 4.9 | T10: 1.58 | V10: 8.1 | X10: 7.2
C11: 9 | D11: 310 | F11: 8.5956528 | H11: 8.8431077 | J11: 2.4953757 | L11: 10.122816 | N11: 8.2542615 | P11: 8.6 | Q11: 0 | R11: 8 | T11: 2.34 | V11: 9.8 | X11: 8.3 | Y11: M
C12: 10 | D12: 310 | F12: 9.6984335 | H12: 13.284635 | J12: 3.4438736 | L12: 11.892056 | N12: 9.3132433 | P12: 9.7 | Q12: 0 | R12: 12.2 | T12: 3.24 | V12: 11.6 | X12: 9.3
C13: 11 | D13: 310 | F13: 10.774737 | H13: 18.867609 | J13: 4.5238399 | L13: 13.629721 | N13: 10.3468 | P13: 10.8 | Q13: 0 | R13: 17.4 | T13: 4.29 | V13: 13.3 | X13: 10.4 | Y13: M
C14: 12 | D14: 310 | F14: 11.818953 | H14: 25.607902 | J14: 5.716911 | L14: 15.321951 | N14: 11.349543 | P14: 11.9 | Q14: 0 | R14: 23.8 | T14: 5.45 | V14: 15 | X14: 11.4 | Y14: M
C15: 13 | D15: 310 | F15: 12.827064 | H15: 33.478897 | J15: 7.0031656 | L15: 16.958231 | N15: 12.317615 | P15: 12.9 | Q15: 0 | R15: 31.4 | T15: 6.71 | V15: 16.6 | X15: 12.4
C16: 14 | D16: 310 | F16: 13.796317 | H16: 42.420033 | J16: 8.3627942 | L16: 18.531435 | N16: 13.248372 | P16: 13.8 | Q16: 0 | R16: 40 | T16: 8.06 | V16: 18.2 | X16: 13.3 | Y16: M
C17: 15 | D17: 310 | F17: 14.724959 | H17: 52.343521 | J17: 9.776743 | L17: 20.036896 | N17: 14.140132 | P17: 14.8 | Q17: 0 | R17: 49.7 | T17: 9.47 | V17: 19.8 | X17: 14.2
C18: 16 | D18: 310 | F18: 15.612037 | H18: 63.145276 | J18: 11.227876 | L18: 21.472478 | N18: 14.991977 | P18: 15.6 | Q18: 0 | R18: 60.3 | T18: 10.93 | V18: 21.3 | X18: 15 | Y18: M
C19: 17 | D19: 310 | F19: 16.457222 | H19: 74.714083 | J19: 12.701546 | L19: 22.838188 | N19: 15.803595 | P19: 16.5 | Q19: 0 | R19: 71.7 | T19: 12.43 | V19: 22.7 | X19: 15.8
C20: 18 | D20: 310 | F20: 17.260685 | H20: 86.93488 | J20: 14.185132 | L20: 24.135152 | N20: 16.575147 | P20: 17.3 | Q20: 0 | R20: 83.9 | T20: 13.94 | V20: 24 | X20: 16.6 | Y20: M
C21: 19 | D21: 310 | F21: 18.022981 | H21: 99.697689 | J21: 15.668672 | L21: 25.365852 | N21: 17.307167 | P21: 18 | Q21: 0 | R21: 96.7 | T21: 15.47 | V21: 25.3 | X21: 17.3
C22: 20 | D22: 310 | F22: 18.744965 | H22: 112.83084 | J22: 17.133953 | L22: 26.525412 | N22: 18.000476 | P22: 18.8 | Q22: 0 | R22: 110 | T22: 16.99 | V22: 26.5 | X22: 18
C23: 21 | D23: 310 | F23: 19.427715 | H23: 126.4736 | J23: 18.610393 | L23: 27.644652 | N23: 18.65611 | P23: 19.4 | Q23: 0 | R23: 123.8 | T23: 18.52 | V23: 27.7 | X23: 18.7 | Y23: M
C24: 22 | D24: 310 | F24: 20.072481 | H24: 140.60392 | J24: 20.10041 | L24: 28.730012 | N24: 19.275267 | P24: 20.1 | Q24: 0 | R24: 138.2 | T24: 20.07 | V24: 28.9 | X24: 19.3
C25: 23 | D25: 310 | F25: 20.680631 | H25: 155.15951 | J25: 21.600261 | L25: 29.782617 | N25: 19.859264 | P25: 20.7 | Q25: 0 | R25: 153.1 | T25: 21.64 | V25: 30 | X25: 19.9
C26: 24 | D26: 310 | F26: 21.253615 | H26: 170.08045 | J26: 23.106595 | L26: 30.80359 | N26: 20.40949 | P26: 21.3 | Q26: 0 | R26: 168.3 | T26: 23.22 | V26: 31.1 | X26: 20.4
C27: 25 | D27: 310 | F27: 21.792933 | H27: 185.30974 | J27: 24.616434 | L27: 31.794055 | N27: 20.927389 | P27: 21.8 | Q27: 0 | R27: 184 | T27: 24.81 | V27: 32.2 | X27: 20.9
C28: 26 | D28: 309.58208 | F28: 22.300113 | H28: 200.60663 | J28: 26.102791 | L28: 32.761952 | N28: 21.415552 | P28: 22.3 | Q28: 0 | R28: 200 | T28: 26.41 | V28: 33.2 | X28: 21.4
C29: 27 | D29: 308.82776 | F29: 22.776684 | H29: 215.92709 | J29: 27.565498 | L29: 33.708463 | N29: 21.875302 | P29: 22.8 | Q29: 0 | R29: 216.2 | T29: 28 | V29: 34.3 | X29: 21.9
C30: 28 | D30: 307.99876 | F30: 23.224167 | H30: 231.3309 | J30: 29.016913 | L30: 34.631023 | N30: 22.307417 | P30: 23.2 | Q30: 0 | R30: 232.6 | T30: 29.59 | V30: 35.3 | X30: 22.3
A31: HighUC | B31: 25.4 | C31: 0 | D31: 1000 | F31: 0.25 | H31: 0.0064 | J31: 0 | L31: 0 | N31: 0.23298249 | P31: 0.3 | Q31: 0 | R31: 0 | T31: 0 | V31: 0 | X31: 0.2
C32: 1 | D32: 1000 | F32: 0.57418873 | H32: 0.033737581 | J32: 0 | L32: 0 | N32: 0.53510367 | P32: 0.5 | Q32: 0 | R32: 0 | T32: 0 | V32: 0 | X32: 0.5
C33: 2 | D33: 1000 | F33: 1.2320062 | H33: 0.18404012 | J33: 0 | L33: 0 | N33: 1.1481435 | P33: 1.1 | Q33: 0 | R33: 0 | T33: 0 | V33: 0 | X33: 1
C34: 3 | D34: 1000 | F34: 2.0837734 | H34: 0.53726913 | J34: 0.016695527 | L34: 0.46101416 | N34: 1.9419309 | P34: 1.9 | Q34: 0 | R34: 0 | T34: 0.01 | V34: 0.3 | X34: 1.7
C35: 4 | D35: 1000 | F35: 3.0602596 | H35: 1.1607089 | J35: 0.23358204 | L35: 1.7243838 | N35: 2.8519476 | P35: 2.7 | Q35: 0 | R35: 0.5 | T35: 0.17 | V35: 1.5 | X35: 2.6
C36: 5 | D36: 1000 | F36: 4.1159482 | H36: 2.1149266 | J36: 0.83918734 | L36: 3.2684637 | N36: 3.8357754 | P36: 3.7 | Q36: 0 | R36: 1.7 | T36: 0.71 | V36: 3.1 | X36: 3.5
C37: 6 | D37: 1000 | F37: 5.2184243 | H37: 3.3094597 | J37: 1.2294491 | L37: 3.9561202 | N37: 4.8632059 | O37: 550 | P37: 4.7 | Q37: 0 | R37: 4.3 | S37: 4.3 | T37: 1.73 | U37: 1.73 | V37: 4.9 | W37: 4.9 | X37: 4.4 | Y37: TW
C38: 7 | D38: 1000 | F38: 6.343767 | H38: 3.6213568 | J38: 1.2294491 | L38: 3.9561202 | N38: 5.9119465 | P38: 5.7 | Q38: 0 | R38: 5.5 | T38: 2.04 | V38: 6.9 | X38: 5.4
C39: 8 | D39: 1000 | F39: 7.4740265 | H39: 5.7496011 | J39: 1.7766484 | L39: 4.7557054 | N39: 6.9652692 | P39: 6.8 | Q39: 0 | R39: 9.9 | T39: 3.36 | V39: 8.8 | X39: 6.4
C40: 9 | D40: 1000 | F40: 8.5956528 | H40: 9.4087587 | J40: 2.6549929 | L40: 5.8136098 | N40: 8.0105463 | O40: 250 | P40: 7.8 | Q40: 0 | R40: 16.1 | S40: 16.1 | T40: 5.01 | U40: 5.01 | V40: 10.8 | W40: 10.8 | X40: 7.3 | Y40: TW
...

Sheet yield_tables_R
B1: A1808 | D1: A1809 | F1: A1810 | H1: A1811 | J1: A1835 | L1: A1838 | N1: A1841 | P1: A1862 | R1: A1863 | T1: A1864 | V1: A1868 | X1: A1870 | Z1: A2027 | AB1: A2028 | AD1: A2037 | AF1: A2056 | AH1: A2064 | AJ1: A2075 | AL1: A2088 | AN1: A2269 | AP1: A2282 | AR1: A2406 | AT1: A2408 | AV1: A2409 | AX1: A2410 | AZ1: A2411 | BB1: A2412 | BD1: A2413 | BF1: A2414 | BH1: A2415 | BJ1: A2416 | BL1: A2417 | BN1: A2418 | BP1: A2419 | BR1: A2420 | BT1: A2549 | BV1: A2550 | BX1: A2552 | BZ1: A2554 | CB1: A2560 | CD1: A2561 | CF1: A2563 | CH1: A2564 | CJ1: A2565 | CL1: A2567 | CN1: A2568 | CP1: A2569 | CR1: A2570 | CT1: A2571 | CV1: A2572
A2: Row Labels | B2: VB | C2: R | D2: VB | E2: R | F2: VB | G2: R | H2: VB | I2: R | J2: VB | K2: R | L2: VB | M2: R | N2: VB | O2: R | P2: VB | Q2: R | R2: VB | S2: R | T2: VB | U2: R | V2: VB | W2: R | X2: VB | Y2: R | Z2: VB | AA2: R | AB2: VB | AC2: R | AD2: VB | AE2: R | AF2: VB | AG2: R | AH2: VB | AI2: R | AJ2: VB | AK2: R | AL2: VB | AM2: R | AN2: VB | AO2: R | AP2: VB | AQ2: R | AR2: VB | AS2: R | AT2: VB | AU2: R | AV2: VB | AW2: R | AX2: VB | AY2: R | AZ2: VB | BA2: R | BB2: VB | BC2: R | BD2: VB | BE2: R | BF2: VB | BG2: R | BH2: VB | BI2: R | BJ2: VB | BK2: R | BL2: VB | BM2: R | BN2: VB | BO2: R | BP2: VB | BQ2: R | BR2: VB | BS2: R | BT2: VB | BU2: R | BV2: VB | BW2: R | BX2: VB | BY2: R | BZ2: VB | CA2: R | CB2: VB | CC2: R | CD2: VB | CE2: R | CF2: VB | CG2: R | CH2: VB | CI2: R | CJ2: VB | CK2: R | CL2: VB | CM2: R | CN2: VB | CO2: R | CP2: VB | CQ2: R | CR2: VB | CS2: R | CT2: VB | CU2: R | CV2: VB | CW2: R
A3: =Sheet2!A6 -> 0 | B3: =Sheet2!B6 -> 310 | C3: =Sheet2!C6 -> 310 | D3: =Sheet2!D6 -> 925 | E3: =Sheet2!E6 -> 925 | F3: =Sheet2!F6 -> 1400 | G3: =Sheet2!G6 -> 1400 | H3: =Sheet2!H6 -> 1050 | ... CW3: =Sheet2!CW6 -> 260
A4: =Sheet2!A7 -> 1 | B4: =Sheet2!B7 -> 310 | C4: =Sheet2!C7 -> 310 | D4: =Sheet2!D7 -> 925 | E4: =Sheet2!E7 -> 925 | F4: =Sheet2!F7 -> 1400 | G4: =Sheet2!G7 -> 1400 | H4: =Sheet2!H7 -> 1050 | ... CW4: =Sheet2!CW7 -> 260
A5: =Sheet2!A8 -> 2 | B5: =Sheet2!B8 -> 310 | C5: =Sheet2!C8 -> 310 | D5: =Sheet2!D8 -> 925 | E5: =Sheet2!E8 -> 925 | F5: =Sheet2!F8 -> 1400 | G5: =Sheet2!G8 -> 1400 | H5: =Sheet2!H8 -> 1050 | ... CW5: =Sheet2!CW8 -> 260
A6: =Sheet2!A9 -> 3 | B6: =Sheet2!B9 -> 310 | C6: =Sheet2!C9 -> 310 | D6: =Sheet2!D9 -> 924.8 | E6: =Sheet2!E9 -> 925 | F6: =Sheet2!F9 -> 1399.6 | G6: =Sheet2!G9 -> 1400 | H6: =Sheet2!H9 -> 1049.5 | ... CW6: =Sheet2!CW9 -> 259.9
A7: =Sheet2!A10 -> 4 | B7: =Sheet2!B10 -> 310 | C7: =Sheet2!C10 -> 309.9 | D7: =Sheet2!D10 -> 924.4 | E7: =Sheet2!E10 -> 924.6 | F7: =Sheet2!F10 -> 1399 | G7: =Sheet2!G10 -> 1399.4 | H7: =Sheet2!H10 -> 1049 | ... CW7: =Sheet2!CW10 -> 259.8
A8: =Sheet2!A11 -> 5 | B8: =Sheet2!B11 -> 310 | C8: =Sheet2!C11 -> 309.7 | D8: =Sheet2!D11 -> 924 | E8: =Sheet2!E11 -> 924.2 | F8: =Sheet2!F11 -> 1398.3 | G8: =Sheet2!G11 -> 1398.7 | H8: =Sheet2!H11 -> 1048.5 | ... CW8: =Sheet2!CW11 -> 259.6
A9: =Sheet2!A12 -> 6 | B9: =Sheet2!B12 -> 310 | C9: =Sheet2!C12 -> 309.6 | D9: =Sheet2!D12 -> 923.5 | E9: =Sheet2!E12 -> 923.7 | F9: =Sheet2!F12 -> 1397.7 | G9: =Sheet2!G12 -> 1398.1 | H9: =Sheet2!H12 -> 1048 | ... CW9: =Sheet2!CW12 -> 259.5
A10: =Sheet2!A13 -> 7 | B10: =Sheet2!B13 -> 310 | C10: =Sheet2!C13 -> 309.4 | D10: =Sheet2!D13 -> 549.7 | E10: =Sheet2!E13 -> 550 | F10: =Sheet2!F13 -> 824.6 | G10: =Sheet2!G13 -> 825 | H10: =Sheet2!H13 -> 675 | ... CW10: =Sheet2!CW13 -> 259.4
A11: =Sheet2!A14 -> 8 | B11: =Sheet2!B14 -> 310 | C11: =Sheet2!C14 -> 309.3 | D11: =Sheet2!D14 -> 549.5 | E11: =Sheet2!E14 -> 549.7 | F11: =Sheet2!F14 -> 824.2 | G11: =Sheet2!G14 -> 824.6 | H11: =Sheet2!H14 -> 675 | ... CW11: =Sheet2!CW14 -> 259.3
A12: =Sheet2!A15 -> 9 | B12: =Sheet2!B15 -> 310 | C12: =Sheet2!C15 -> 309.1 | D12: =Sheet2!D15 -> 549.2 | E12: =Sheet2!E15 -> 549.5 | F12: =Sheet2!F15 -> 823.8 | G12: =Sheet2!G15 -> 824.2 | H12: =Sheet2!H15 -> 675 | ... CW12: =Sheet2!CW15 -> 259.2
A13: =Sheet2!A16 -> 10 | B13: =Sheet2!B16 -> 310 | C13: =Sheet2!C16 -> 309 | D13: =Sheet2!D16 -> 250 | E13: =Sheet2!E16 -> 549.2 | F13: =Sheet2!F16 -> 823.4 | G13: =Sheet2!G16 -> 823.8 | H13: =Sheet2!H16 -> 674.7 | ... CW13: =Sheet2!CW16 -> 259
A14: =Sheet2!A17 -> 11 | B14: =Sheet2!B17 -> 310 | C14: =Sheet2!C17 -> 308.9 | D14: =Sheet2!D17 -> 250 | E14: =Sheet2!E17 -> 250 | F14: =Sheet2!F17 -> 822.9 | G14: =Sheet2!G17 -> 823.4 | H14: =Sheet2!H17 -> 673.8 | ... CW14: =Sheet2!CW17 -> 258.9
... A31: =Sheet2!A34 -> 28 | B31: =Sheet2!B34 -> 308 | C31: =Sheet2!C34 -> 302.7 | D31: =Sheet2!D34 -> 247.2 | E31: =Sheet2!E34 -> 245.8 | F31: =Sheet2!F34 -> 337.3 | G31: =Sheet2!G34 -> 332.5 | H31: =Sheet2!H34 -> 568.8 | ... CW31: =Sheet2!CW34 -> 251.9

Sheet Sheet1
A1: Plot | B1: Age | C1: Stocking b4 thin VBA | D1: Stocking aft thin VBA | E1: Age | F1: Stocking b4 thin | G1: Stocking aft thin
A2: LowUC | B2: 0 | C2: 310 | E2: 0 | F2: 310
A3: LowUC | B3: 1 | C3: 310 | E3: 1 | F3: 310
A4: LowUC | B4: 2 | C4: 310 | E4: 2 | F4: 310
A5: LowUC | B5: 3 | C5: 310 | E5: 3 | F5: 310
A6: LowUC | B6: 4 | C6: 310 | E6: 4 | F6: 310
A7: LowUC | B7: 5 | C7: 310 | E7: 5 | F7: 310
A8: LowUC | B8: 6 | C8: 310 | E8: 6 | F8: 310
A9: LowUC | B9: 7 | C9: 310 | E9: 7 | F9: 310
A10: LowUC | B10: 8 | C10: 310 | E10: 8 | F10: 310
A11: LowUC | B11: 9 | C11: 310 | E11: 9 | F11: 310
A12: LowUC | B12: 10 | C12: 310 | E12: 10 | F12: 310
A13: LowUC | B13: 11 | C13: 310 | E13: 11 | F13: 310
... A65: HighT2 | B65: 5 | C65: 998.89875 | E65: 5 | F65: 999.08221
A66: HighT2 | B66: 6 | C66: 998.44016 | D66: 550 | E66: 6 | F66: 999.08221 | G66: 550
A67: HighT2 | B67: 7 | C67: 549.74735 | E67: 7 | F67: 550
A68: HighT2 | B68: 8 | C68: 549.49363 | E68: 8 | F68: 549.74724
A69: HighT2 | B69: 9 | C69: 549.2354 | D69: 250 | E69: 9 | F69: 549.49296
A70: HighT2 | B70: 10 | C70: 250 | E70: 10 | F70: 549.49296 | G70: 250
A71: HighT2 | B71: 11 | C71: 250 | E71: 11 | F71: 250
A72: HighT2 | B72: 12 | C72: 250 | E72: 12 | F72: 250
A73: HighT2 | B73: 13 | C73: 250 | E73: 13 | F73: 250
A74: HighT2 | B74: 14 | C74: 250 | E74: 14 | F74: 250
A75: HighT2 | B75: 15 | C75: 250 | E75: 15 | F75: 250
A76: HighT2 | B76: 16 | C76: 250 | E76: 16 | F76: 250
A77: HighT2 | B77: 17 | C77: 250 | E77: 17 | F77: 250
A78: HighT2 | B78: 18 | C78: 250 | E78: 18 | F78: 250
A79: HighT2 | B79: 19 | C79: 250 | E79: 19 | F79: 250
A80: HighT2 | B80: 20 | C80: 250 | E80: 20 | F80: 250
A81: HighT2 | B81: 21 | C81: 249.97264 | E81: 21 | F81: 250
A82: HighT2 | B82: 22 | C82: 249.68306 | E82: 22 | F82: 250
... A98: HighT1 | B98: 9 | C98: 995.18531 | E98: 9 | F98: 995.80313
A99: HighT1 | B99: 10 | C99: 992.71096 | D99: 270 | E99: 10 | F99: 993.73585
A100: HighT1 | B100: 11 | C100: 270 | E100: 11 | F100: 993.73585 | G100: 270
A101: HighT1 | B101: 12 | C101: 270 | E101: 12 | F101: 270
A102: HighT1 | B102: 13 | C102: 270 | E102: 13 | F102: 270
A103: HighT1 | B103: 14 | C103: 270 | E103: 14 | F103: 270
A104: HighT1 | B104: 15 | C104: 270 | E104: 15 | F104: 270
A105: HighT1 | B105: 16 | C105: 270 | E105: 16 | F105: 270
A106: HighT1 | B106: 17 | C106: 270 | E106: 17 | F106: 270
...

Sheet Sheet3
A1: A1809 | F1: Plot | G1: Age | H1: Stocking b4 thin_VBA | I1: Stocking aft thin_VBA | J1: Stocking b4 thin_R | K1: Stocking aft thin_R
A2: A1809 | F2: A1809 | G2: 0 | H2: 925 | J2: 925
A3: A1810 | F3: A1809 | G3: 1 | H3: 925 | J3: 925
A4: A1810 | F4: A1809 | G4: 2 | H4: 925 | J4: 925
A5: A1811 | F5: A1809 | G5: 3 | H5: 924.8 | J5: 925
A6: A1835 | F6: A1809 | G6: 4 | H6: 924.4 | J6: 924.6
A7: A1838 | F7: A1809 | G7: 5 | H7: 924 | J7: 924.2
A8: A1841 | F8: A1809 | G8: 6 | H8: 923.5 | I8: 550 | J8: 923.7 | K8: 550
A9: A2027 | F9: A1809 | G9: 7 | H9: 549.7 | J9: 550
A10: A2028 | F10: A1809 | G10: 8 | H10: 549.5 | J10: 549.7
A11: A2037 | F11: A1809 | G11: 9 | H11: 549.2 | I11: 250 | J11: 549.5 | K11: 250
A12: A2269 | F12: A1809 | G12: 10 | H12: 250 | J12: 549.2 | K12: 250 | L12: ?
A13: A2269 | F13: A1809 | G13: 11 | H13: 250 | J13: 250
A14: A2282 | F14: A1809 | G14: 12 | H14: 250 | J14: 249.9
F15: A1809 | G15: 13 | H15: 250 | J15: 249.8
F16: A1809 | G16: 14 | H16: 250 | J16: 249.6
F17: A1809 | G17: 15 | H17: 250 | J17: 249.5
F18: A1809 | G18: 16 | H18: 250 | J18: 249.4
F19: A1809 | G19: 17 | H19: 250 | J19: 249.2
F20: A1809 | G20: 18 | H20: 250 | J20: 249
F21: A1809 | G21: 19 | H21: 250 | J21: 248.9
F22: A1809 | G22: 20 | H22: 250 | J22: 248.6
F23: A1809 | G23: 21 | H23: 250 | J23: 248.4
F24: A1809 | G24: 22 | H24: 249.7 | J24: 248.1
F25: A1809 | G25: 23 | H25: 249.4 | J25: 247.9
F26: A1809 | G26: 24 | H26: 249 | J26: 247.5
... F36: A1810 | G36: 5 | H36: 1398.3 | J36: 1398.7
F37: A1810 | G37: 6 | H37: 1397.7 | I37: 825 | J37: 1398.1 | K37: 825
F38: A1810 | G38: 7 | H38: 824.6 | J38: 825
F39: A1810 | G39: 8 | H39: 824.2 | J39: 824.6
F40: A1810 | G40: 9 | H40: 823.8 | J40: 824.2
F41: A1810 | G41: 10 | H41: 823.4 | J41: 823.8
F42: A1810 | G42: 11 | H42: 822.9 | I42: 400 | J42: 823.4 | K42: 400
F43: A1810 | G43: 12 | H43: 395.5 | J43: 400
F44: A1810 | G44: 13 | H44: 391.1 | J44: 399.8 | K44: 340 | L44: ?
F45: A1810 | G45: 14 | H45: 386.7 | J45: 340
F46: A1810 | G46: 15 | H46: 382.3 | J46: 339.8
F47: A1810 | G47: 16 | H47: 378.1 | J47: 339.6
F48: A1810 | G48: 17 | H48: 373.8 | J48: 339.3
F49: A1810 | G49: 18 | H49: 369.6 | J49: 339
...
